Traceback (most recent call last):
  File "/Users/aysanaghazadeh/University/Pitt/Research/Milos/wave_form_data/ECG_PPG_project/classification/main.py", line 8, in <module>
    train_loader, test_loader = prepare_dataset(config)
  File "/Users/aysanaghazadeh/University/Pitt/Research/Milos/wave_form_data/ECG_PPG_project/classification/src/utils.py", line 35, in prepare_dataset
    return dataset(config)
  File "/Users/aysanaghazadeh/University/Pitt/Research/Milos/wave_form_data/ECG_PPG_project/classification/src/utils.py", line 14, in prepare_ptb_dataset
    label = pd.read_csv(label_file, index_col='ecg_id')
  File "/Users/aysanaghazadeh/opt/anaconda3/envs/ECG_PPG_project/lib/python3.9/site-packages/pandas/io/parsers/readers.py", line 912, in read_csv
    return _read(filepath_or_buffer, kwds)
  File "/Users/aysanaghazadeh/opt/anaconda3/envs/ECG_PPG_project/lib/python3.9/site-packages/pandas/io/parsers/readers.py", line 577, in _read
    parser = TextFileReader(filepath_or_buffer, **kwds)
  File "/Users/aysanaghazadeh/opt/anaconda3/envs/ECG_PPG_project/lib/python3.9/site-packages/pandas/io/parsers/readers.py", line 1407, in __init__
    self._engine = self._make_engine(f, self.engine)
  File "/Users/aysanaghazadeh/opt/anaconda3/envs/ECG_PPG_project/lib/python3.9/site-packages/pandas/io/parsers/readers.py", line 1661, in _make_engine
    self.handles = get_handle(
  File "/Users/aysanaghazadeh/opt/anaconda3/envs/ECG_PPG_project/lib/python3.9/site-packages/pandas/io/common.py", line 859, in get_handle
    handle = open(
FileNotFoundError: [Errno 2] No such file or directory: '../../data/ptb-xl-a-large-publicly-available-electrocardiography-dataset-1.0.3/ptbxl_database.csv'