
1686258105.985088
  0%|          | 0/1000 [00:34<?, ?it/s]
Traceback (most recent call last):
  File "/Users/aysanaghazadeh/University/Pitt/Research/Milos/wave_form_data/ECG_PPG_project/classification/main.py", line 11, in <module>
    train.train(train_loader, test_loader)
  File "/Users/aysanaghazadeh/University/Pitt/Research/Milos/wave_form_data/ECG_PPG_project/classification/src/train.py", line 57, in train
    return self.trains[self.config.model] \
  File "/Users/aysanaghazadeh/University/Pitt/Research/Milos/wave_form_data/ECG_PPG_project/classification/src/train.py", line 24, in train
    for (i, (ecg, label)) in enumerate(train_loader):
  File "/Users/aysanaghazadeh/opt/anaconda3/envs/ECG_PPG_project/lib/python3.9/site-packages/torch/utils/data/dataloader.py", line 633, in __next__
    data = self._next_data()
  File "/Users/aysanaghazadeh/opt/anaconda3/envs/ECG_PPG_project/lib/python3.9/site-packages/torch/utils/data/dataloader.py", line 1345, in _next_data
    return self._process_data(data)
  File "/Users/aysanaghazadeh/opt/anaconda3/envs/ECG_PPG_project/lib/python3.9/site-packages/torch/utils/data/dataloader.py", line 1371, in _process_data
    data.reraise()
  File "/Users/aysanaghazadeh/opt/anaconda3/envs/ECG_PPG_project/lib/python3.9/site-packages/torch/_utils.py", line 644, in reraise
    raise exception
FileNotFoundError: Caught FileNotFoundError in DataLoader worker process 0.
Original Traceback (most recent call last):
  File "/Users/aysanaghazadeh/opt/anaconda3/envs/ECG_PPG_project/lib/python3.9/site-packages/torch/utils/data/_utils/worker.py", line 308, in _worker_loop
    data = fetcher.fetch(index)
  File "/Users/aysanaghazadeh/opt/anaconda3/envs/ECG_PPG_project/lib/python3.9/site-packages/torch/utils/data/_utils/fetch.py", line 51, in fetch
    data = [self.dataset[idx] for idx in possibly_batched_index]
  File "/Users/aysanaghazadeh/opt/anaconda3/envs/ECG_PPG_project/lib/python3.9/site-packages/torch/utils/data/_utils/fetch.py", line 51, in <listcomp>
    data = [self.dataset[idx] for idx in possibly_batched_index]
  File "/Users/aysanaghazadeh/University/Pitt/Research/Milos/wave_form_data/ECG_PPG_project/classification/src/dataset.py", line 14, in __getitem__
    x = wfdb.rdsamp(self.file_paths[item])
  File "/Users/aysanaghazadeh/opt/anaconda3/envs/ECG_PPG_project/lib/python3.9/site-packages/wfdb/io/record.py", line 2317, in rdsamp
    record = rdrecord(
  File "/Users/aysanaghazadeh/opt/anaconda3/envs/ECG_PPG_project/lib/python3.9/site-packages/wfdb/io/record.py", line 2029, in rdrecord
    record = rdheader(record_name, pn_dir=pn_dir, rd_segments=False)
  File "/Users/aysanaghazadeh/opt/anaconda3/envs/ECG_PPG_project/lib/python3.9/site-packages/wfdb/io/record.py", line 1839, in rdheader
    with open(
FileNotFoundError: [Errno 2] No such file or directory: '/Users/aysanaghazadeh/University/Pitt/Research/Milos/wave_form_data/ECG_PPG_project/data/ptb-xl-a-large-publicly-available-electrocardiography-dataset-1.0.3records100/13000/13719_lr.hea'